<?xml version="1.0" ?>
<robot xmlns:xacro="http://ros.org/wiki/xacro">
  <xacro:macro name="motoman_hc10" params="prefix">
    <xacro:include filename="$(find motoman_resources)/urdf/common_materials.xacro"/>

    <!-- link list -->
    <link name="world"/>

    <link name="${prefix}base_link">
      <visual>
        <geometry>
          <mesh filename="package://motoman_hc10_support/meshes/hc10/visual/base_link.dae"/>
        </geometry>
        <xacro:material_yaskawa_blue/>
      </visual>
      <inertial>
        <origin xyz="0 0 0" rpy="0 0 0"/>
        <mass value="0.1"/>
        <inertia ixx="0.03" ixy="0.03" ixz="0.03" iyy="0.0" iyz="0.0" izz="0.0"/>
      </inertial>
      <collision>
        <geometry>
          <mesh filename="package://motoman_hc10_support/meshes/hc10/collision/base_link.stl"/>
        </geometry>
      </collision>
    </link>

    <link name="${prefix}link_1_s">
      <visual>
        <geometry>
          <mesh filename="package://motoman_hc10_support/meshes/hc10/visual/link_1_s.dae"/>
        </geometry>
        <xacro:material_yaskawa_blue/>
      </visual>
      <inertial>
        <origin xyz="0 0 0" rpy="0 0 0"/>
        <mass value="0.1"/>
        <inertia ixx="0.03" ixy="0.03" ixz="0.03" iyy="0.0" iyz="0.0" izz="0.0"/>
      </inertial>
      <collision>
        <geometry>
          <mesh filename="package://motoman_hc10_support/meshes/hc10/collision/link_1_s.stl"/>
        </geometry>
      </collision>
    </link>

    <link name="${prefix}link_2_l">
      <visual>
        <geometry>
          <mesh filename="package://motoman_hc10_support/meshes/hc10/visual/link_2_l.dae"/>
        </geometry>
        <xacro:material_yaskawa_blue/>
      </visual>
      <inertial>
        <origin xyz="0 0 0" rpy="0 0 0"/>
        <mass value="0.1"/>
        <inertia ixx="0.03" ixy="0.03" ixz="0.03" iyy="0.0" iyz="0.0" izz="0.0"/>
      </inertial>
      <collision>
        <geometry>
          <mesh filename="package://motoman_hc10_support/meshes/hc10/collision/link_2_l.stl"/>
        </geometry>
      </collision>
    </link>

    <link name="${prefix}link_3_u">
      <visual>
        <geometry>
          <mesh filename="package://motoman_hc10_support/meshes/hc10/visual/link_3_u.dae"/>
        </geometry>
        <xacro:material_yaskawa_blue/>
      </visual>
      <inertial>
        <origin xyz="0 0 0" rpy="0 0 0"/>
        <mass value="0.1"/>
        <inertia ixx="0.03" ixy="0.03" ixz="0.03" iyy="0.0" iyz="0.0" izz="0.0"/>
      </inertial>
      <collision>
        <geometry>
          <mesh filename="package://motoman_hc10_support/meshes/hc10/collision/link_3_u.stl"/>
        </geometry>
      </collision>
    </link>

    <link name="${prefix}link_4_r">
      <visual>
        <geometry>
          <mesh filename="package://motoman_hc10_support/meshes/hc10/visual/link_4_r.dae"/>
        </geometry>
        <xacro:material_yaskawa_blue/>
      </visual>
      <inertial>
        <origin xyz="0 0 0" rpy="0 0 0"/>
        <mass value="0.1"/>
        <inertia ixx="0.03" ixy="0.03" ixz="0.03" iyy="0.0" iyz="0.0" izz="0.0"/>
      </inertial>
      <collision>
        <geometry>
          <mesh filename="package://motoman_hc10_support/meshes/hc10/collision/link_4_r.stl"/>
        </geometry>
      </collision>
    </link>

    <link name="${prefix}link_5_b">
      <visual>
        <geometry>
          <mesh filename="package://motoman_hc10_support/meshes/hc10/visual/link_5_b.dae"/>
        </geometry>
        <xacro:material_yaskawa_blue/>
      </visual>
      <inertial>
        <origin xyz="0 0 0" rpy="0 0 0"/>
        <mass value="0.1"/>
        <inertia ixx="0.03" ixy="0.03" ixz="0.03" iyy="0.0" iyz="0.0" izz="0.0"/>
      </inertial>
      <collision>
        <geometry>
          <mesh filename="package://motoman_hc10_support/meshes/hc10/collision/link_5_b.stl"/>
        </geometry>
      </collision>
    </link>

    <link name="${prefix}link_6_t">
      <visual>
        <geometry>
          <mesh filename="package://motoman_hc10_support/meshes/hc10/visual/link_6_t.dae"/>
        </geometry>
        <xacro:material_yaskawa_blue/>
      </visual>
      <inertial>
        <origin xyz="0 0 0" rpy="0 0 0"/>
        <mass value="0.1"/>
        <inertia ixx="0.03" ixy="0.03" ixz="0.03" iyy="0.0" iyz="0.0" izz="0.0"/>
      </inertial>
      <collision>
        <geometry>
          <mesh filename="package://motoman_hc10_support/meshes/hc10/collision/link_6_t.stl"/>
        </geometry>
      </collision>
    </link>

    <link name="${prefix}tool0"/>
    <!-- end of link list -->

    <!-- joint list -->
    <joint name="world_fixed" type="fixed">
      <parent link="world"/>
      <child link="${prefix}base_link"/>
      <origin xyz="0 0 0" rpy="0 0 0"/>
    </joint>

    <joint name="${prefix}joint_1_s" type="revolute">
      <parent link="${prefix}base_link"/>
      <child link="${prefix}link_1_s"/>
      <origin xyz="0 0 0.275" rpy="0 0 0" />
      <axis xyz="0 0 1" />
      <limit lower="${radians(-180)}" upper="${radians(180)}" effort="368.48" velocity="${radians(130)}"/>
      <dynamics damping="1"/>
    </joint>

    <joint name="${prefix}joint_2_l" type="revolute">
      <parent link="${prefix}link_1_s"/>
      <child link="${prefix}link_2_l"/>
      <origin xyz="0 0 0" rpy="0 0 0" />
      <axis xyz="0 1 0" />
      <limit lower="${radians(-180)}" upper="${radians(180)}" effort="368.48" velocity="${radians(130)}"/>
      <dynamics damping="1"/>
    </joint>

    <joint name="${prefix}joint_3_u" type="revolute">
      <parent link="${prefix}link_2_l"/>
      <child link="${prefix}link_3_u"/>
      <origin xyz="0 0 0.700" rpy="0 0 0" />
      <axis xyz="0 -1 0" />
      <limit lower="${radians(-5)}" upper="${radians(355)}" effort="141.12" velocity="${radians(180)}"/>
      <dynamics damping="1"/>
    </joint>

    <joint name="${prefix}joint_4_r" type="revolute">
      <parent link="${prefix}link_3_u"/>
      <child link="${prefix}link_4_r"/>
      <origin xyz="0 0 -0.500" rpy="0 0 0" />
      <axis xyz="0 0 1" />
      <limit lower="${radians(-180)}" upper="${radians(180)}" effort="39.20" velocity="${radians(180)}"/>
      <dynamics damping="1"/>
    </joint>

    <joint name="${prefix}joint_5_b" type="revolute">
      <parent link="${prefix}link_4_r"/>
      <child link="${prefix}link_5_b"/>
      <origin xyz="0 0.162 0" rpy="0 0 0" />
      <axis xyz="0 -1 0" />
      <limit lower="${radians(-180)}" upper="${radians(180)}" effort="31.36" velocity="${radians(250)}"/>
      <dynamics damping="1"/>
    </joint>

    <joint name="${prefix}joint_6_t" type="revolute">
      <parent link="${prefix}link_5_b"/>
      <child link="${prefix}link_6_t"/>
      <origin xyz="0 0 0" rpy="0 0 0" />
      <axis xyz="0 0 1" />
      <limit lower="${radians(-180)}" upper="${radians(180)}" effort="31.36" velocity="${radians(250)}"/>
      <dynamics damping="1"/>
    </joint>

    <joint name="${prefix}joint_6_t-tool0" type="fixed">
      <origin xyz="0 0 -0.130" rpy="${pi} 0 0"/>
      <parent link="${prefix}link_6_t"/>
      <child link="${prefix}tool0"/>
    </joint>
    <!-- end of joint list -->

    <!-- ROS base_link to Robot Manufacturer World Coordinates transform -->
    <link name="${prefix}base" />

    <joint name="${prefix}base_link-base" type="fixed">
      <origin xyz="0 0 0.275" rpy="0 0 0"/>
      <parent link="${prefix}base_link"/>
      <child link="${prefix}base"/>
    </joint>

  </xacro:macro>

  <gazebo reference="camera_depth_frame">
    <sensor name="kinect_camera" type="depth">
      <update_rate>20</update_rate>
      <camera>
        <horizontal_fov>1.047198</horizontal_fov>
        <image>
          <width>640</width>
          <height>480</height>
          <format>B8G8R8</format>
        </image>
        <clip>
          <near>0.05</near>
          <far>3</far>
        </clip>
      </camera>
      <plugin name="kinect_controller" filename="libgazebo_ros_openni_kinect.so">
        <baseline>0.1</baseline>
        <alwaysOn>true</alwaysOn>
        <updateRate>10</updateRate>
        <cameraName>camera_ir</cameraName>
        <imageTopicName>/camera/color/image_raw</imageTopicName>
        <cameraInfoTopicName>/camera/color/camera_info</cameraInfoTopicName>
        <depthImageTopicName>/camera/depth/image_raw</depthImageTopicName>
        <depthImageCameraInfoTopicName>/camera/depth/camera_info</depthImageCameraInfoTopicName>
        <pointCloudTopicName>/camera/depth/points</pointCloudTopicName>
        <frameName>camera_depth_optical_frame</frameName>
        <distortion_k1>0.0</distortion_k1>
        <distortion_k2>0.0</distortion_k2>
        <distortion_k3>0.0</distortion_k3>
        <distortion_t1>0.0</distortion_t1>
        <distortion_t2>0.0</distortion_t2>
        <pointCloudCutoff>0.16</pointCloudCutoff>
        <pointCloudCutoffMax>10.0</pointCloudCutoffMax>
      </plugin>
    </sensor>
  </gazebo>

</robot>
